Workbook

Sheet Summary (fix)
A2: DIVISION | B2: Athelete | C2: Stage 1 | D2: Points | E2: Stage 2 | F2: Points2 | G2: Stage 3 | H2: Points3 | I2: Rank | J2: Total | L2: LA LIGA - STAGE PHASE
A3: MALE A | B3: João Barreto | C3: =_xlfn.XLOOKUP(Table65[[#This Row],[Athelete]],Table15722354466784681112[Athlete],Table15722354466784681112[Rank],"-") -> 4th | D3: =_xlfn.XLOOKUP(C3,Table39[Rank],Table39[Points],0) -> 1100 | E3: =_xlfn.XLOOKUP(Table65[[#This Row],[Athelete]],Table152028325060721017145161[Athlete],Table152028325060721017145161[Rank],"-") -> 1st | F3: =_xlfn.XLOOKUP(E3,Table39[Rank],Table39[Points],0) -> 1500 | H3: =_xlfn.XLOOKUP(G3,Table39[Rank],Table39[Points],0) -> 0 | I3: =IF(RANK(Table65[[#This Row],[Total]],Table65[Total])=1,$M$5,IF(RANK(Table65[[#This Row],[Total]],Table65[Total])=2,$M$6,IF(RANK(Table65[[#This Row],[Total]],Table65[Total])=3,$M$7,RANK(Table65[[#This Row],[Total]],Table65[Total])&"th"))) -> 1st | J3: =SUM(D3,F3,H3) -> 2600 | L3: Critério de desempate: | M3: Points per Rank
B4: Bruno Soares | C4: =_xlfn.XLOOKUP(Table65[[#This Row],[Athelete]],Table15722354466784681112[Athlete],Table15722354466784681112[Rank],"-") -> 1st | D4: =_xlfn.XLOOKUP(C4,Table39[Rank],Table39[Points],0) -> 1500 | E4: =_xlfn.XLOOKUP(Table65[[#This Row],[Athelete]],Table152028325060721017145161[Athlete],Table152028325060721017145161[Rank],"-") -> 6th | F4: =_xlfn.XLOOKUP(E4,Table39[Rank],Table39[Points],0) -> 900 | H4: =_xlfn.XLOOKUP(G4,Table39[Rank],Table39[Points],0) -> 0 | I4: =IF(RANK(Table65[[#This Row],[Total]],Table65[Total])=1,$M$5,IF(RANK(Table65[[#This Row],[Total]],Table65[Total])=2,$M$6,IF(RANK(Table65[[#This Row],[Total]],Table65[Total])=3,$M$7,RANK(Table65[[#This Row],[Total]],Table65[Total])&"th"))) -> 2nd | J4: =SUM(D4,F4,H4) -> 2400 | L4: 1- Número de vitórias | M4: Rank | N4: Points
B5: Bruno Montini | C5: =_xlfn.XLOOKUP(Table65[[#This Row],[Athelete]],Table15722354466784681112[Athlete],Table15722354466784681112[Rank],"-") -> 5th | D5: =_xlfn.XLOOKUP(C5,Table39[Rank],Table39[Points],0) -> 1000 | E5: =_xlfn.XLOOKUP(Table65[[#This Row],[Athelete]],Table152028325060721017145161[Athlete],Table152028325060721017145161[Rank],"-") -> 5th | F5: =_xlfn.XLOOKUP(E5,Table39[Rank],Table39[Points],0) -> 1000 | H5: =_xlfn.XLOOKUP(G5,Table39[Rank],Table39[Points],0) -> 0 | I5: =IF(RANK(Table65[[#This Row],[Total]],Table65[Total])=1,$M$5,IF(RANK(Table65[[#This Row],[Total]],Table65[Total])=2,$M$6,IF(RANK(Table65[[#This Row],[Total]],Table65[Total])=3,$M$7,RANK(Table65[[#This Row],[Total]],Table65[Total])&"th"))) -> 3rd | J5: =SUM(D5,F5,H5) -> 2000 | L5: 2- Saldo pontos | M5: 1st | N5: 1500
B6: Thyago Henrique | C6: =_xlfn.XLOOKUP(Table65[[#This Row],[Athelete]],Table15722354466784681112[Athlete],Table15722354466784681112[Rank],"-") -> 9th | D6: =_xlfn.XLOOKUP(C6,Table39[Rank],Table39[Points],0) -> 350 | E6: =_xlfn.XLOOKUP(Table65[[#This Row],[Athelete]],Table152028325060721017145161[Athlete],Table152028325060721017145161[Rank],"-") -> 2nd | F6: =_xlfn.XLOOKUP(E6,Table39[Rank],Table39[Points],0) -> 1300 | H6: =_xlfn.XLOOKUP(G6,Table39[Rank],Table39[Points],0) -> 0 | I6: =IF(RANK(Table65[[#This Row],[Total]],Table65[Total])=1,$M$5,IF(RANK(Table65[[#This Row],[Total]],Table65[Total])=2,$M$6,IF(RANK(Table65[[#This Row],[Total]],Table65[Total])=3,$M$7,RANK(Table65[[#This Row],[Total]],Table65[Total])&"th"))) -> 4th | J6: =SUM(D6,F6,H6) -> 1650 | L6: 3- Pontos marcados | M6: 2nd | N6: 1300
B7: Pedro Nagib | C7: =_xlfn.XLOOKUP(Table65[[#This Row],[Athelete]],Table15722354466784681112[Athlete],Table15722354466784681112[Rank],"-") -> 2nd | D7: =_xlfn.XLOOKUP(C7,Table39[Rank],Table39[Points],0) -> 1300 | E7: =_xlfn.XLOOKUP(Table65[[#This Row],[Athelete]],Table152028325060721017145161[Athlete],Table152028325060721017145161[Rank],"-") -> - | F7: =_xlfn.XLOOKUP(E7,Table39[Rank],Table39[Points],0) -> 0 | H7: =_xlfn.XLOOKUP(G7,Table39[Rank],Table39[Points],0) -> 0 | I7: =IF(RANK(Table65[[#This Row],[Total]],Table65[Total])=1,$M$5,IF(RANK(Table65[[#This Row],[Total]],Table65[Total])=2,$M$6,IF(RANK(Table65[[#This Row],[Total]],Table65[Total])=3,$M$7,RANK(Table65[[#This Row],[Total]],Table65[Total])&"th"))) -> 5th | J7: =SUM(D7,F7,H7) -> 1300 | L7: 4- Menos pontos sofridos | M7: 3rd | N7: 1200
B8: Eduardo Ferreira | C8: =_xlfn.XLOOKUP(Table65[[#This Row],[Athelete]],Table15722354466784681112[Athlete],Table15722354466784681112[Rank],"-") -> 3rd | D8: =_xlfn.XLOOKUP(C8,Table39[Rank],Table39[Points],0) -> 1200 | E8: =_xlfn.XLOOKUP(Table65[[#This Row],[Athelete]],Table152028325060721017145161[Athlete],Table152028325060721017145161[Rank],"-") -> - | F8: =_xlfn.XLOOKUP(E8,Table39[Rank],Table39[Points],0) -> 0 | H8: =_xlfn.XLOOKUP(G8,Table39[Rank],Table39[Points],0) -> 0 | I8: =IF(RANK(Table65[[#This Row],[Total]],Table65[Total])=1,$M$5,IF(RANK(Table65[[#This Row],[Total]],Table65[Total])=2,$M$6,IF(RANK(Table65[[#This Row],[Total]],Table65[Total])=3,$M$7,RANK(Table65[[#This Row],[Total]],Table65[Total])&"th"))) -> 6th | J8: =SUM(D8,F8,H8) -> 1200 | L8: 5- Confronto direto | M8: 4th | N8: 1100
B9: Gerardo Torres | C9: =_xlfn.XLOOKUP(Table65[[#This Row],[Athelete]],Table15722354466784681112[Athlete],Table15722354466784681112[Rank],"-") -> - | D9: =_xlfn.XLOOKUP(C9,Table39[Rank],Table39[Points],0) -> 0 | E9: =_xlfn.XLOOKUP(Table65[[#This Row],[Athelete]],Table152028325060721017145161[Athlete],Table152028325060721017145161[Rank],"-") -> 3rd | F9: =_xlfn.XLOOKUP(E9,Table39[Rank],Table39[Points],0) -> 1200 | H9: =_xlfn.XLOOKUP(G9,Table39[Rank],Table39[Points],0) -> 0 | I9: =IF(RANK(Table65[[#This Row],[Total]],Table65[Total])=1,$M$5,IF(RANK(Table65[[#This Row],[Total]],Table65[Total])=2,$M$6,IF(RANK(Table65[[#This Row],[Total]],Table65[Total])=3,$M$7,RANK(Table65[[#This Row],[Total]],Table65[Total])&"th"))) -> 6th | J9: =SUM(D9,F9,H9) -> 1200 | L9: 6- Maior saldo no confronto direto | M9: 5th | N9: 1000
B10: Victor Alemão | C10: =_xlfn.XLOOKUP(Table65[[#This Row],[Athelete]],Table15722354466784681112[Athlete],Table15722354466784681112[Rank],"-") -> - | D10: =_xlfn.XLOOKUP(C10,Table39[Rank],Table39[Points],0) -> 0 | E10: =_xlfn.XLOOKUP(Table65[[#This Row],[Athelete]],Table152028325060721017145161[Athlete],Table152028325060721017145161[Rank],"-") -> 4th | F10: =_xlfn.XLOOKUP(E10,Table39[Rank],Table39[Points],0) -> 1100 | H10: =_xlfn.XLOOKUP(G10,Table39[Rank],Table39[Points],0) -> 0 | I10: =IF(RANK(Table65[[#This Row],[Total]],Table65[Total])=1,$M$5,IF(RANK(Table65[[#This Row],[Total]],Table65[Total])=2,$M$6,IF(RANK(Table65[[#This Row],[Total]],Table65[Total])=3,$M$7,RANK(Table65[[#This Row],[Total]],Table65[Total])&"th"))) -> 8th | J10: =SUM(D10,F10,H10) -> 1100 | L10: 7- Mais pontos marcados no confronto direto | M10: 6th | N10: 900
B11: Thomas Zahn | C11: =_xlfn.XLOOKUP(Table65[[#This Row],[Athelete]],Table15722354466784681112[Athlete],Table15722354466784681112[Rank],"-") -> 12th | D11: =_xlfn.XLOOKUP(C11,Table39[Rank],Table39[Points],0) -> 200 | E11: =_xlfn.XLOOKUP(Table65[[#This Row],[Athelete]],Table152028325060721017145161[Athlete],Table152028325060721017145161[Rank],"-") -> 7th | F11: =_xlfn.XLOOKUP(E11,Table39[Rank],Table39[Points],0) -> 800 | H11: =_xlfn.XLOOKUP(G11,Table39[Rank],Table39[Points],0) -> 0 | I11: =IF(RANK(Table65[[#This Row],[Total]],Table65[Total])=1,$M$5,IF(RANK(Table65[[#This Row],[Total]],Table65[Total])=2,$M$6,IF(RANK(Table65[[#This Row],[Total]],Table65[Total])=3,$M$7,RANK(Table65[[#This Row],[Total]],Table65[Total])&"th"))) -> 9th | J11: =SUM(D11,F11,H11) -> 1000 | L11: 8- Menos pontos sofridos no confronto direto | M11: 7th | N11: 800
B12: Renan Guiot | C12: =_xlfn.XLOOKUP(Table65[[#This Row],[Athelete]],Table15722354466784681112[Athlete],Table15722354466784681112[Rank],"-") -> 7th | D12: =_xlfn.XLOOKUP(C12,Table39[Rank],Table39[Points],0) -> 800 | E12: =_xlfn.XLOOKUP(Table65[[#This Row],[Athelete]],Table152028325060721017145161[Athlete],Table152028325060721017145161[Rank],"-") -> 12th | F12: =_xlfn.XLOOKUP(E12,Table39[Rank],Table39[Points],0) -> 200 | H12: =_xlfn.XLOOKUP(G12,Table39[Rank],Table39[Points],0) -> 0 | I12: 10th | J12: =SUM(D12,F12,H12) -> 1000 | L12: 9- Sorteio (1ºao4º) Empate (5º&6º) | M12: 8th | N12: 700
B13: Gabriel Bugao | C13: =_xlfn.XLOOKUP(Table65[[#This Row],[Athelete]],Table15722354466784681112[Athlete],Table15722354466784681112[Rank],"-") -> 6th | D13: =_xlfn.XLOOKUP(C13,Table39[Rank],Table39[Points],0) -> 900 | E13: =_xlfn.XLOOKUP(Table65[[#This Row],[Athelete]],Table152028325060721017145161[Athlete],Table152028325060721017145161[Rank],"-") -> - | F13: =_xlfn.XLOOKUP(E13,Table39[Rank],Table39[Points],0) -> 0 | H13: =_xlfn.XLOOKUP(G13,Table39[Rank],Table39[Points],0) -> 0 | I13: =IF(RANK(Table65[[#This Row],[Total]],Table65[Total])=1,$M$5,IF(RANK(Table65[[#This Row],[Total]],Table65[Total])=2,$M$6,IF(RANK(Table65[[#This Row],[Total]],Table65[Total])=3,$M$7,RANK(Table65[[#This Row],[Total]],Table65[Total])&"th"))) -> 11th | J13: =SUM(D13,F13,H13) -> 900 | L13: 10- Atleta em grupo mais dificil (grupo do campeao, i.e.) | M13: 9th | N13: 350
B14: David Aitkens | C14: =_xlfn.XLOOKUP(Table65[[#This Row],[Athelete]],Table15722354466784681112[Athlete],Table15722354466784681112[Rank],"-") -> 8th | D14: =_xlfn.XLOOKUP(C14,Table39[Rank],Table39[Points],0) -> 700 | E14: =_xlfn.XLOOKUP(Table65[[#This Row],[Athelete]],Table152028325060721017145161[Athlete],Table152028325060721017145161[Rank],"-") -> - | F14: =_xlfn.XLOOKUP(E14,Table39[Rank],Table39[Points],0) -> 0 | H14: =_xlfn.XLOOKUP(G14,Table39[Rank],Table39[Points],0) -> 0 | I14: =IF(RANK(Table65[[#This Row],[Total]],Table65[Total])=1,$M$5,IF(RANK(Table65[[#This Row],[Total]],Table65[Total])=2,$M$6,IF(RANK(Table65[[#This Row],[Total]],Table65[Total])=3,$M$7,RANK(Table65[[#This Row],[Total]],Table65[Total])&"th"))) -> 12th | J14: =SUM(D14,F14,H14) -> 700 | M14: 10th | N14: 300
B15: Jose Hermano | C15: =_xlfn.XLOOKUP(Table65[[#This Row],[Athelete]],Table15722354466784681112[Athlete],Table15722354466784681112[Rank],"-") -> - | D15: =_xlfn.XLOOKUP(C15,Table39[Rank],Table39[Points],0) -> 0 | E15: =_xlfn.XLOOKUP(Table65[[#This Row],[Athelete]],Table152028325060721017145161[Athlete],Table152028325060721017145161[Rank],"-") -> 8th | F15: =_xlfn.XLOOKUP(E15,Table39[Rank],Table39[Points],0) -> 700 | H15: =_xlfn.XLOOKUP(G15,Table39[Rank],Table39[Points],0) -> 0 | I15: 13th | J15: =SUM(D15,F15,H15) -> 700 | L15: LA LIGA - GENERAL | M15: 11th | N15: 250
B16: Guilherme Nascimento | C16: =_xlfn.XLOOKUP(Table65[[#This Row],[Athelete]],Table15722354466784681112[Athlete],Table15722354466784681112[Rank],"-") -> 14th | D16: =_xlfn.XLOOKUP(C16,Table39[Rank],Table39[Points],0) -> 100 | E16: =_xlfn.XLOOKUP(Table65[[#This Row],[Athelete]],Table152028325060721017145161[Athlete],Table152028325060721017145161[Rank],"-") -> 9th | F16: =_xlfn.XLOOKUP(E16,Table39[Rank],Table39[Points],0) -> 350 | H16: =_xlfn.XLOOKUP(G16,Table39[Rank],Table39[Points],0) -> 0 | I16: =IF(RANK(Table65[[#This Row],[Total]],Table65[Total])=1,$M$5,IF(RANK(Table65[[#This Row],[Total]],Table65[Total])=2,$M$6,IF(RANK(Table65[[#This Row],[Total]],Table65[Total])=3,$M$7,RANK(Table65[[#This Row],[Total]],Table65[Total])&"th"))) -> 14th | J16: =SUM(D16,F16,H16) -> 450 | L16: Critério de desempate: | M16: 12th | N16: 200
B17: Gabriel Velloso | C17: =_xlfn.XLOOKUP(Table65[[#This Row],[Athelete]],Table15722354466784681112[Athlete],Table15722354466784681112[Rank],"-") -> 15th | D17: =_xlfn.XLOOKUP(C17,Table39[Rank],Table39[Points],0) -> 50 | E17: =_xlfn.XLOOKUP(Table65[[#This Row],[Athelete]],Table152028325060721017145161[Athlete],Table152028325060721017145161[Rank],"-") -> 11th | F17: =_xlfn.XLOOKUP(E17,Table39[Rank],Table39[Points],0) -> 250 | H17: =_xlfn.XLOOKUP(G17,Table39[Rank],Table39[Points],0) -> 0 | I17: =IF(RANK(Table65[[#This Row],[Total]],Table65[Total])=1,$M$5,IF(RANK(Table65[[#This Row],[Total]],Table65[Total])=2,$M$6,IF(RANK(Table65[[#This Row],[Total]],Table65[Total])=3,$M$7,RANK(Table65[[#This Row],[Total]],Table65[Total])&"th"))) -> 15th | J17: =SUM(D17,F17,H17) -> 300 | L17: 1- Maior quantidade de Stages jogados | M17: 13th | N17: 150
B18: Daniel Gaspar | C18: =_xlfn.XLOOKUP(Table65[[#This Row],[Athelete]],Table15722354466784681112[Athlete],Table15722354466784681112[Rank],"-") -> 10th | D18: =_xlfn.XLOOKUP(C18,Table39[Rank],Table39[Points],0) -> 300 | E18: =_xlfn.XLOOKUP(Table65[[#This Row],[Athelete]],Table152028325060721017145161[Athlete],Table152028325060721017145161[Rank],"-") -> - | F18: =_xlfn.XLOOKUP(E18,Table39[Rank],Table39[Points],0) -> 0 | H18: =_xlfn.XLOOKUP(G18,Table39[Rank],Table39[Points],0) -> 0 | I18: 16th | J18: =SUM(D18,F18,H18) -> 300 | L18: 2- Melhores colocações conquistadas | M18: 14th | N18: 100
B19: Alex Abrantes | C19: =_xlfn.XLOOKUP(Table65[[#This Row],[Athelete]],Table15722354466784681112[Athlete],Table15722354466784681112[Rank],"-") -> 11th | D19: =_xlfn.XLOOKUP(C19,Table39[Rank],Table39[Points],0) -> 250 | E19: =_xlfn.XLOOKUP(Table65[[#This Row],[Athelete]],Table152028325060721017145161[Athlete],Table152028325060721017145161[Rank],"-") -> - | F19: =_xlfn.XLOOKUP(E19,Table39[Rank],Table39[Points],0) -> 0 | H19: =_xlfn.XLOOKUP(G19,Table39[Rank],Table39[Points],0) -> 0 | I19: =IF(RANK(Table65[[#This Row],[Total]],Table65[Total])=1,$M$5,IF(RANK(Table65[[#This Row],[Total]],Table65[Total])=2,$M$6,IF(RANK(Table65[[#This Row],[Total]],Table65[Total])=3,$M$7,RANK(Table65[[#This Row],[Total]],Table65[Total])&"th"))) -> 17th | J19: =SUM(D19,F19,H19) -> 250 | L19: 3- Stage de confronto direto | M19: 15th | N19: 50
B20: Bernardo Trotta | C20: =_xlfn.XLOOKUP(Table65[[#This Row],[Athelete]],Table15722354466784681112[Athlete],Table15722354466784681112[Rank],"-") -> 13th | D20: =_xlfn.XLOOKUP(C20,Table39[Rank],Table39[Points],0) -> 150 | E20: =_xlfn.XLOOKUP(Table65[[#This Row],[Athelete]],Table152028325060721017145161[Athlete],Table152028325060721017145161[Rank],"-") -> - | F20: =_xlfn.XLOOKUP(E20,Table39[Rank],Table39[Points],0) -> 0 | H20: =_xlfn.XLOOKUP(G20,Table39[Rank],Table39[Points],0) -> 0 | I20: =IF(RANK(Table65[[#This Row],[Total]],Table65[Total])=1,$M$5,IF(RANK(Table65[[#This Row],[Total]],Table65[Total])=2,$M$6,IF(RANK(Table65[[#This Row],[Total]],Table65[Total])=3,$M$7,RANK(Table65[[#This Row],[Total]],Table65[Total])&"th"))) -> 18th | J20: =SUM(D20,F20,H20) -> 150 | L20: 4- Stage com maiores # de atletas | M20: 16th | N20: 10
A22: DIVISION | B22: Athelete | C22: Stage 1 | D22: Points | E22: Stage 2 | F22: Points2 | G22: Stage 3 | H22: Points3 | I22: Rank | J22: Total
A23: FEMALE A | B23: Gabriela | C23: =_xlfn.XLOOKUP(Table82[[#This Row],[Athelete]],Table1520283250607210171105[Athlete],Table1520283250607210171105[Rank],"-") -> 1st | D23: =_xlfn.XLOOKUP(C23,Table39[Rank],Table39[Points],0) -> 1500 | E23: =_xlfn.XLOOKUP(Table82[[#This Row],[Athelete]],Table15202832506072101714577175[Athlete],Table15202832506072101714577175[Rank],"-") -> 2nd | F23: =_xlfn.XLOOKUP(E23,Table39[Rank],Table39[Points],0) -> 1300 | H23: =_xlfn.XLOOKUP(G23,Table39[Rank],Table39[Points],0) -> 0 | I23: =IF(RANK(Table82[[#This Row],[Total]],Table82[Total])=1,$M$5,IF(RANK(Table82[[#This Row],[Total]],Table82[Total])=2,$M$6,IF(RANK(Table82[[#This Row],[Total]],Table82[Total])=3,$M$7,RANK(Table82[[#This Row],[Total]],Table82[Total])&"th"))) -> 1st | J23: =SUM(D23,F23,H23) -> 2800
B24: Fiorella | C24: =_xlfn.XLOOKUP(Table82[[#This Row],[Athelete]],Table1520283250607210171105[Athlete],Table1520283250607210171105[Rank],"-") -> 4th | D24: =_xlfn.XLOOKUP(C24,Table39[Rank],Table39[Points],0) -> 1100 | E24: =_xlfn.XLOOKUP(Table82[[#This Row],[Athelete]],Table15202832506072101714577175[Athlete],Table15202832506072101714577175[Rank],"-") -> 1st | F24: =_xlfn.XLOOKUP(E24,Table39[Rank],Table39[Points],0) -> 1500 | H24: =_xlfn.XLOOKUP(G24,Table39[Rank],Table39[Points],0) -> 0 | I24: =IF(RANK(Table82[[#This Row],[Total]],Table82[Total])=1,$M$5,IF(RANK(Table82[[#This Row],[Total]],Table82[Total])=2,$M$6,IF(RANK(Table82[[#This Row],[Total]],Table82[Total])=3,$M$7,RANK(Table82[[#This Row],[Total]],Table82[Total])&"th"))) -> 2nd | J24: =SUM(D24,F24,H24) -> 2600
B25: Roberta G. | C25: =_xlfn.XLOOKUP(Table82[[#This Row],[Athelete]],Table1520283250607210171105[Athlete],Table1520283250607210171105[Rank],"-") -> 7th | D25: =_xlfn.XLOOKUP(C25,Table39[Rank],Table39[Points],0) -> 800 | E25: =_xlfn.XLOOKUP(Table82[[#This Row],[Athelete]],Table15202832506072101714577175[Athlete],Table15202832506072101714577175[Rank],"-") -> 3rd | F25: =_xlfn.XLOOKUP(E25,Table39[Rank],Table39[Points],0) -> 1200 | H25: =_xlfn.XLOOKUP(G25,Table39[Rank],Table39[Points],0) -> 0 | I25: =IF(RANK(Table82[[#This Row],[Total]],Table82[Total])=1,$M$5,IF(RANK(Table82[[#This Row],[Total]],Table82[Total])=2,$M$6,IF(RANK(Table82[[#This Row],[Total]],Table82[Total])=3,$M$7,RANK(Table82[[#This Row],[Total]],Table82[Total])&"th"))) -> 3rd | J25: =SUM(D25,F25,H25) -> 2000
B26: Bella | C26: =_xlfn.XLOOKUP(Table82[[#This Row],[Athelete]],Table1520283250607210171105[Athlete],Table1520283250607210171105[Rank],"-") -> 6th | D26: =_xlfn.XLOOKUP(C26,Table39[Rank],Table39[Points],0) -> 900 | E26: =_xlfn.XLOOKUP(Table82[[#This Row],[Athelete]],Table15202832506072101714577175[Athlete],Table15202832506072101714577175[Rank],"-") -> 4th | F26: =_xlfn.XLOOKUP(E26,Table39[Rank],Table39[Points],0) -> 1100 | H26: =_xlfn.XLOOKUP(G26,Table39[Rank],Table39[Points],0) -> 0 | I26: 4th | J26: =SUM(D26,F26,H26) -> 2000
B27: Giovanna | C27: =_xlfn.XLOOKUP(Table82[[#This Row],[Athelete]],Table1520283250607210171105[Athlete],Table1520283250607210171105[Rank],"-") -> 5th | D27: =_xlfn.XLOOKUP(C27,Table39[Rank],Table39[Points],0) -> 1000 | E27: =_xlfn.XLOOKUP(Table82[[#This Row],[Athelete]],Table15202832506072101714577175[Athlete],Table15202832506072101714577175[Rank],"-") -> 5th | F27: =_xlfn.XLOOKUP(E27,Table39[Rank],Table39[Points],0) -> 1000 | H27: =_xlfn.XLOOKUP(G27,Table39[Rank],Table39[Points],0) -> 0 | I27: 5th | J27: =SUM(D27,F27,H27) -> 2000
B28: Janelle | C28: =_xlfn.XLOOKUP(Table82[[#This Row],[Athelete]],Table1520283250607210171105[Athlete],Table1520283250607210171105[Rank],"-") -> 8th | D28: =_xlfn.XLOOKUP(C28,Table39[Rank],Table39[Points],0) -> 700 | E28: =_xlfn.XLOOKUP(Table82[[#This Row],[Athelete]],Table15202832506072101714577175[Athlete],Table15202832506072101714577175[Rank],"-") -> 6th | F28: =_xlfn.XLOOKUP(E28,Table39[Rank],Table39[Points],0) -> 900 | H28: =_xlfn.XLOOKUP(G28,Table39[Rank],Table39[Points],0) -> 0 | I28: =IF(RANK(Table82[[#This Row],[Total]],Table82[Total])=1,$M$5,IF(RANK(Table82[[#This Row],[Total]],Table82[Total])=2,$M$6,IF(RANK(Table82[[#This Row],[Total]],Table82[Total])=3,$M$7,RANK(Table82[[#This Row],[Total]],Table82[Total])&"th"))) -> 6th | J28: =SUM(D28,F28,H28) -> 1600
B29: Talita | C29: =_xlfn.XLOOKUP(Table82[[#This Row],[Athelete]],Table1520283250607210171105[Athlete],Table1520283250607210171105[Rank],"-") -> 2nd | D29: =_xlfn.XLOOKUP(C29,Table39[Rank],Table39[Points],0) -> 1300 | E29: =_xlfn.XLOOKUP(Table82[[#This Row],[Athelete]],Table15202832506072101714577175[Athlete],Table15202832506072101714577175[Rank],"-") -> - | F29: =_xlfn.XLOOKUP(E29,Table39[Rank],Table39[Points],0) -> 0 | H29: =_xlfn.XLOOKUP(G29,Table39[Rank],Table39[Points],0) -> 0 | I29: =IF(RANK(Table82[[#This Row],[Total]],Table82[Total])=1,$M$5,IF(RANK(Table82[[#This Row],[Total]],Table82[Total])=2,$M$6,IF(RANK(Table82[[#This Row],[Total]],Table82[Total])=3,$M$7,RANK(Table82[[#This Row],[Total]],Table82[Total])&"th"))) -> 7th | J29: =SUM(D29,F29,H29) -> 1300
B30: Priscila | C30: =_xlfn.XLOOKUP(Table82[[#This Row],[Athelete]],Table1520283250607210171105[Athlete],Table1520283250607210171105[Rank],"-") -> 3rd | D30: =_xlfn.XLOOKUP(C30,Table39[Rank],Table39[Points],0) -> 1200 | E30: =_xlfn.XLOOKUP(Table82[[#This Row],[Athelete]],Table15202832506072101714577175[Athlete],Table15202832506072101714577175[Rank],"-") -> - | F30: =_xlfn.XLOOKUP(E30,Table39[Rank],Table39[Points],0) -> 0 | H30: =_xlfn.XLOOKUP(G30,Table39[Rank],Table39[Points],0) -> 0 | I30: =IF(RANK(Table82[[#This Row],[Total]],Table82[Total])=1,$M$5,IF(RANK(Table82[[#This Row],[Total]],Table82[Total])=2,$M$6,IF(RANK(Table82[[#This Row],[Total]],Table82[Total])=3,$M$7,RANK(Table82[[#This Row],[Total]],Table82[Total])&"th"))) -> 8th | J30: =SUM(D30,F30,H30) -> 1200
B31: Julia C. | C31: =_xlfn.XLOOKUP(Table82[[#This Row],[Athelete]],Table1520283250607210171105[Athlete],Table1520283250607210171105[Rank],"-") -> 10th | D31: =_xlfn.XLOOKUP(C31,Table39[Rank],Table39[Points],0) -> 300 | E31: =_xlfn.XLOOKUP(Table82[[#This Row],[Athelete]],Table15202832506072101714577175[Athlete],Table15202832506072101714577175[Rank],"-") -> 7th | F31: =_xlfn.XLOOKUP(E31,Table39[Rank],Table39[Points],0) -> 800 | H31: =_xlfn.XLOOKUP(G31,Table39[Rank],Table39[Points],0) -> 0 | I31: =IF(RANK(Table82[[#This Row],[Total]],Table82[Total])=1,$M$5,IF(RANK(Table82[[#This Row],[Total]],Table82[Total])=2,$M$6,IF(RANK(Table82[[#This Row],[Total]],Table82[Total])=3,$M$7,RANK(Table82[[#This Row],[Total]],Table82[Total])&"th"))) -> 9th | J31: =SUM(D31,F31,H31) -> 1100
B32: Natalia | C32: =_xlfn.XLOOKUP(Table82[[#This Row],[Athelete]],Table1520283250607210171105[Athlete],Table1520283250607210171105[Rank],"-") -> - | D32: =_xlfn.XLOOKUP(C32,Table39[Rank],Table39[Points],0) -> 0 | E32: =_xlfn.XLOOKUP(Table82[[#This Row],[Athelete]],Table15202832506072101714577175[Athlete],Table15202832506072101714577175[Rank],"-") -> 8th | F32: =_xlfn.XLOOKUP(E32,Table39[Rank],Table39[Points],0) -> 700 | H32: =_xlfn.XLOOKUP(G32,Table39[Rank],Table39[Points],0) -> 0 | I32: =IF(RANK(Table82[[#This Row],[Total]],Table82[Total])=1,$M$5,IF(RANK(Table82[[#This Row],[Total]],Table82[Total])=2,$M$6,IF(RANK(Table82[[#This Row],[Total]],Table82[Total])=3,$M$7,RANK(Table82[[#This Row],[Total]],Table82[Total])&"th"))) -> 10th | J32: =SUM(D32,F32,H32) -> 700
B33: Paula F. | C33: =_xlfn.XLOOKUP(Table82[[#This Row],[Athelete]],Table1520283250607210171105[Athlete],Table1520283250607210171105[Rank],"-") -> 9th | D33: =_xlfn.XLOOKUP(C33,Table39[Rank],Table39[Points],0) -> 350 | E33: =_xlfn.XLOOKUP(Table82[[#This Row],[Athelete]],Table15202832506072101714577175[Athlete],Table15202832506072101714577175[Rank],"-") -> - | F33: =_xlfn.XLOOKUP(E33,Table39[Rank],Table39[Points],0) -> 0 | H33: =_xlfn.XLOOKUP(G33,Table39[Rank],Table39[Points],0) -> 0 | I33: =IF(RANK(Table82[[#This Row],[Total]],Table82[Total])=1,$M$5,IF(RANK(Table82[[#This Row],[Total]],Table82[Total])=2,$M$6,IF(RANK(Table82[[#This Row],[Total]],Table82[Total])=3,$M$7,RANK(Table82[[#This Row],[Total]],Table82[Total])&"th"))) -> 11th | J33: =SUM(D33,F33,H33) -> 350
B34: Beesan | C34: =_xlfn.XLOOKUP(Table82[[#This Row],[Athelete]],Table1520283250607210171105[Athlete],Table1520283250607210171105[Rank],"-") -> 11th | D34: =_xlfn.XLOOKUP(C34,Table39[Rank],Table39[Points],0) -> 250 | E34: =_xlfn.XLOOKUP(Table82[[#This Row],[Athelete]],Table15202832506072101714577175[Athlete],Table15202832506072101714577175[Rank],"-") -> - | F34: =_xlfn.XLOOKUP(E34,Table39[Rank],Table39[Points],0) -> 0 | H34: =_xlfn.XLOOKUP(G34,Table39[Rank],Table39[Points],0) -> 0 | I34: =IF(RANK(Table82[[#This Row],[Total]],Table82[Total])=1,$M$5,IF(RANK(Table82[[#This Row],[Total]],Table82[Total])=2,$M$6,IF(RANK(Table82[[#This Row],[Total]],Table82[Total])=3,$M$7,RANK(Table82[[#This Row],[Total]],Table82[Total])&"th"))) -> 12th | J34: =SUM(D34,F34,H34) -> 250
B35: Maria Luisa | C35: =_xlfn.XLOOKUP(Table82[[#This Row],[Athelete]],Table1520283250607210171105[Athlete],Table1520283250607210171105[Rank],"-") -> 12th | D35: =_xlfn.XLOOKUP(C35,Table39[Rank],Table39[Points],0) -> 200 | E35: =_xlfn.XLOOKUP(Table82[[#This Row],[Athelete]],Table15202832506072101714577175[Athlete],Table15202832506072101714577175[Rank],"-") -> - | F35: =_xlfn.XLOOKUP(E35,Table39[Rank],Table39[Points],0) -> 0 | H35: =_xlfn.XLOOKUP(G35,Table39[Rank],Table39[Points],0) -> 0 | I35: =IF(RANK(Table82[[#This Row],[Total]],Table82[Total])=1,$M$5,IF(RANK(Table82[[#This Row],[Total]],Table82[Total])=2,$M$6,IF(RANK(Table82[[#This Row],[Total]],Table82[Total])=3,$M$7,RANK(Table82[[#This Row],[Total]],Table82[Total])&"th"))) -> 13th | J35: =SUM(D35,F35,H35) -> 200
A37: DIVISION | B37: Athelete | C37: Stage 1 | D37: Points | E37: Stage 2 | F37: Points2 | G37: Stage 3 | H37: Points3 | I37: Rank | J37: Total
A38: MALE B | B38: Matheus L. | C38: =_xlfn.XLOOKUP(Table83[[#This Row],[Athelete]],Table1520283250607293215359[Athlete],Table1520283250607293215359[Rank],"-") -> 1st | D38: =_xlfn.XLOOKUP(C38,Table39[Rank],Table39[Points],0) -> 1500 | E38: =_xlfn.XLOOKUP(Table83[[#This Row],[Athelete]],Table152028325060721017145166[Athlete],Table152028325060721017145166[Rank],"-") -> 1st | F38: =_xlfn.XLOOKUP(E38,Table39[Rank],Table39[Points],0) -> 1500 | H38: =_xlfn.XLOOKUP(G38,Table39[Rank],Table39[Points],0) -> 0 | I38: =IF(RANK(Table83[[#This Row],[Total]],Table83[Total])=1,$M$5,IF(RANK(Table83[[#This Row],[Total]],Table83[Total])=2,$M$6,IF(RANK(Table83[[#This Row],[Total]],Table83[Total])=3,$M$7,RANK(Table83[[#This Row],[Total]],Table83[Total])&"th"))) -> 1st | J38: =SUM(D38,F38,H38) -> 3000
B39: Marcelo | C39: =_xlfn.XLOOKUP(Table83[[#This Row],[Athelete]],Table1520283250607293215359[Athlete],Table1520283250607293215359[Rank],"-") -> 4th | D39: =_xlfn.XLOOKUP(C39,Table39[Rank],Table39[Points],0) -> 1100 | E39: =_xlfn.XLOOKUP(Table83[[#This Row],[Athelete]],Table152028325060721017145166[Athlete],Table152028325060721017145166[Rank],"-") -> 2nd | F39: =_xlfn.XLOOKUP(E39,Table39[Rank],Table39[Points],0) -> 1300 | H39: =_xlfn.XLOOKUP(G39,Table39[Rank],Table39[Points],0) -> 0 | I39: =IF(RANK(Table83[[#This Row],[Total]],Table83[Total])=1,$M$5,IF(RANK(Table83[[#This Row],[Total]],Table83[Total])=2,$M$6,IF(RANK(Table83[[#This Row],[Total]],Table83[Total])=3,$M$7,RANK(Table83[[#This Row],[Total]],Table83[Total])&"th"))) -> 2nd | J39: =SUM(D39,F39,H39) -> 2400
B40: Luiz Zuneda | C40: =_xlfn.XLOOKUP(Table83[[#This Row],[Athelete]],Table1520283250607293215359[Athlete],Table1520283250607293215359[Rank],"-") -> 2nd | D40: =_xlfn.XLOOKUP(C40,Table39[Rank],Table39[Points],0) -> 1300 | E40: =_xlfn.XLOOKUP(Table83[[#This Row],[Athelete]],Table152028325060721017145166[Athlete],Table152028325060721017145166[Rank],"-") -> 6th | F40: =_xlfn.XLOOKUP(E40,Table39[Rank],Table39[Points],0) -> 900 | H40: =_xlfn.XLOOKUP(G40,Table39[Rank],Table39[Points],0) -> 0 | I40: =IF(RANK(Table83[[#This Row],[Total]],Table83[Total])=1,$M$5,IF(RANK(Table83[[#This Row],[Total]],Table83[Total])=2,$M$6,IF(RANK(Table83[[#This Row],[Total]],Table83[Total])=3,$M$7,RANK(Table83[[#This Row],[Total]],Table83[Total])&"th"))) -> 3rd | J40: =SUM(D40,F40,H40) -> 2200
B41: Bebeto | C41: =_xlfn.XLOOKUP(Table83[[#This Row],[Athelete]],Table1520283250607293215359[Athlete],Table1520283250607293215359[Rank],"-") -> 3rd | D41: =_xlfn.XLOOKUP(C41,Table39[Rank],Table39[Points],0) -> 1200 | E41: =_xlfn.XLOOKUP(Table83[[#This Row],[Athelete]],Table152028325060721017145166[Athlete],Table152028325060721017145166[Rank],"-") -> 7th | F41: =_xlfn.XLOOKUP(E41,Table39[Rank],Table39[Points],0) -> 800 | H41: =_xlfn.XLOOKUP(G41,Table39[Rank],Table39[Points],0) -> 0 | I41: =IF(RANK(Table83[[#This Row],[Total]],Table83[Total])=1,$M$5,IF(RANK(Table83[[#This Row],[Total]],Table83[Total])=2,$M$6,IF(RANK(Table83[[#This Row],[Total]],Table83[Total])=3,$M$7,RANK(Table83[[#This Row],[Total]],Table83[Total])&"th"))) -> 4th | J41: =SUM(D41,F41,H41) -> 2000
B42: Luka | C42: =_xlfn.XLOOKUP(Table83[[#This Row],[Athelete]],Table1520283250607293215359[Athlete],Table1520283250607293215359[Rank],"-") -> 9th | D42: =_xlfn.XLOOKUP(C42,Table39[Rank],Table39[Points],0) -> 350 | E42: =_xlfn.XLOOKUP(Table83[[#This Row],[Athelete]],Table152028325060721017145166[Athlete],Table152028325060721017145166[Rank],"-") -> 5th | F42: =_xlfn.XLOOKUP(E42,Table39[Rank],Table39[Points],0) -> 1000 | H42: =_xlfn.XLOOKUP(G42,Table39[Rank],Table39[Points],0) -> 0 | I42: =IF(RANK(Table83[[#This Row],[Total]],Table83[Total])=1,$M$5,IF(RANK(Table83[[#This Row],[Total]],Table83[Total])=2,$M$6,IF(RANK(Table83[[#This Row],[Total]],Table83[Total])=3,$M$7,RANK(Table83[[#This Row],[Total]],Table83[Total])&"th"))) -> 5th | J42: =SUM(D42,F42,H42) -> 1350
B43: Rafael | C43: =_xlfn.XLOOKUP(Table83[[#This Row],[Athelete]],Table1520283250607293215359[Athlete],Table1520283250607293215359[Rank],"-") -> 12th | D43: =_xlfn.XLOOKUP(C43,Table39[Rank],Table39[Points],0) -> 200 | E43: =_xlfn.XLOOKUP(Table83[[#This Row],[Athelete]],Table152028325060721017145166[Athlete],Table152028325060721017145166[Rank],"-") -> 4th | F43: =_xlfn.XLOOKUP(E43,Table39[Rank],Table39[Points],0) -> 1100 | H43: =_xlfn.XLOOKUP(G43,Table39[Rank],Table39[Points],0) -> 0 | I43: =IF(RANK(Table83[[#This Row],[Total]],Table83[Total])=1,$M$5,IF(RANK(Table83[[#This Row],[Total]],Table83[Total])=2,$M$6,IF(RANK(Table83[[#This Row],[Total]],Table83[Total])=3,$M$7,RANK(Table83[[#This Row],[Total]],Table83[Total])&"th"))) -> 6th | J43: =SUM(D43,F43,H43) -> 1300
...

Sheet Male A-1
A1: MALE A STAGE 1 GROUP PHASE | B1: GROUP | C1: ATHLETE 1 | D1: ATHLETE 2 | E1: SCORE 1 | F1: SCORE 2 | G1: ATHLETE 3 | H1: X | I1: Y | J1: Z | K1: ATHLETE 4 | L1: SALDO 12 | M1: SALDO 34 | N1: PM 12 | O1: PM 34 | P1: RESULT 12 | Q1: RESULT 34 | S1: MALE A - STAGE 1
B2: A | C2: =B20 -> Guilherme Nascimento | D2: =B23 -> Thyago Henrique | E2: 9 | F2: 18 | G2: =B21 -> Renan Guiot | K2: =B22 -> Gabriel Bugao | L2: =IF(OR(Games_11[[#This Row],[SCORE 1]]="",Games_11[[#This Row],[SCORE 2]]=""),"",Games_11[[#This Row],[SCORE 1]]-Games_11[[#This Row],[SCORE 2]]) -> -9 | M2: =IF(OR(Games_11[[#This Row],[SCORE 1]]="",Games_11[[#This Row],[SCORE 2]]=""),"",Games_11[[#This Row],[SCORE 2]]-Games_11[[#This Row],[SCORE 1]]) -> 9 | N2: =IF(Games_11[[#This Row],[SCORE 1]]="","",Games_11[[#This Row],[SCORE 1]]) -> 9 | O2: =IF(Games_11[[#This Row],[SCORE 2]]="","",Games_11[[#This Row],[SCORE 2]]) -> 18 | P2: =IF(OR(Games_11[[#This Row],[SCORE 1]]="",Games_11[[#This Row],[SCORE 2]]=""),"",IF(Games_11[[#This Row],[SALDO 12]]>0, "WIN","LOSE")) -> LOSE | Q2: =IF(OR(Games_11[[#This Row],[SCORE 1]]="",Games_11[[#This Row],[SCORE 2]]=""),"",IF(Games_11[[#This Row],[SALDO 34]]>0, "WIN","LOSE")) -> WIN | S2: Athlete | T2: Rank
B3: B | C3: =B27 -> Gabriel Velloso | D3: =B30 -> David Aitkens | E3: 18 | F3: 20 | G3: =B28 -> Alex Abrantes | K3: =B29 -> Pedro Nagib | L3: =IF(OR(Games_11[[#This Row],[SCORE 1]]="",Games_11[[#This Row],[SCORE 2]]=""),"",Games_11[[#This Row],[SCORE 1]]-Games_11[[#This Row],[SCORE 2]]) -> -2 | M3: =IF(OR(Games_11[[#This Row],[SCORE 1]]="",Games_11[[#This Row],[SCORE 2]]=""),"",Games_11[[#This Row],[SCORE 2]]-Games_11[[#This Row],[SCORE 1]]) -> 2 | N3: =IF(Games_11[[#This Row],[SCORE 1]]="","",Games_11[[#This Row],[SCORE 1]]) -> 18 | O3: =IF(Games_11[[#This Row],[SCORE 2]]="","",Games_11[[#This Row],[SCORE 2]]) -> 20 | P3: =IF(OR(Games_11[[#This Row],[SCORE 1]]="",Games_11[[#This Row],[SCORE 2]]=""),"",IF(Games_11[[#This Row],[SALDO 12]]>0, "WIN","LOSE")) -> LOSE | Q3: =IF(OR(Games_11[[#This Row],[SCORE 1]]="",Games_11[[#This Row],[SCORE 2]]=""),"",IF(Games_11[[#This Row],[SALDO 34]]>0, "WIN","LOSE")) -> WIN | S3: =IFERROR(_xlfn.XLOOKUP(Table15722354466784681112[[#This Row],[Rank]],$L$39:$Q$39,$L$38:$Q$38),"") -> Bruno Soares | T3: 1st
B4: C | C4: =B34 -> Thomas Zahn | D4: =B37 -> Eduardo Ferreira | E4: 18 | F4: 9 | G4: =B35 -> Daniel Gaspar | K4: =B36 -> Bernardo Trotta | L4: =IF(OR(Games_11[[#This Row],[SCORE 1]]="",Games_11[[#This Row],[SCORE 2]]=""),"",Games_11[[#This Row],[SCORE 1]]-Games_11[[#This Row],[SCORE 2]]) -> 9 | M4: =IF(OR(Games_11[[#This Row],[SCORE 1]]="",Games_11[[#This Row],[SCORE 2]]=""),"",Games_11[[#This Row],[SCORE 2]]-Games_11[[#This Row],[SCORE 1]]) -> -9 | N4: =IF(Games_11[[#This Row],[SCORE 1]]="","",Games_11[[#This Row],[SCORE 1]]) -> 18 | O4: =IF(Games_11[[#This Row],[SCORE 2]]="","",Games_11[[#This Row],[SCORE 2]]) -> 9 | P4: =IF(OR(Games_11[[#This Row],[SCORE 1]]="",Games_11[[#This Row],[SCORE 2]]=""),"",IF(Games_11[[#This Row],[SALDO 12]]>0, "WIN","LOSE")) -> WIN | Q4: =IF(OR(Games_11[[#This Row],[SCORE 1]]="",Games_11[[#This Row],[SCORE 2]]=""),"",IF(Games_11[[#This Row],[SALDO 34]]>0, "WIN","LOSE")) -> LOSE | S4: =IFERROR(_xlfn.XLOOKUP(Table15722354466784681112[[#This Row],[Rank]],$L$39:$Q$39,$L$38:$Q$38),"") -> Pedro Nagib | T4: 2nd
B5: A | C5: =B20 -> Guilherme Nascimento | D5: =B22 -> Gabriel Bugao | E5: 14 | F5: 18 | G5: =B21 -> Renan Guiot | K5: =B24 -> Bruno Montini | L5: =IF(OR(Games_11[[#This Row],[SCORE 1]]="",Games_11[[#This Row],[SCORE 2]]=""),"",Games_11[[#This Row],[SCORE 1]]-Games_11[[#This Row],[SCORE 2]]) -> -4 | M5: =IF(OR(Games_11[[#This Row],[SCORE 1]]="",Games_11[[#This Row],[SCORE 2]]=""),"",Games_11[[#This Row],[SCORE 2]]-Games_11[[#This Row],[SCORE 1]]) -> 4 | N5: =IF(Games_11[[#This Row],[SCORE 1]]="","",Games_11[[#This Row],[SCORE 1]]) -> 14 | O5: =IF(Games_11[[#This Row],[SCORE 2]]="","",Games_11[[#This Row],[SCORE 2]]) -> 18 | P5: =IF(OR(Games_11[[#This Row],[SCORE 1]]="",Games_11[[#This Row],[SCORE 2]]=""),"",IF(Games_11[[#This Row],[SALDO 12]]>0, "WIN","LOSE")) -> LOSE | Q5: =IF(OR(Games_11[[#This Row],[SCORE 1]]="",Games_11[[#This Row],[SCORE 2]]=""),"",IF(Games_11[[#This Row],[SALDO 34]]>0, "WIN","LOSE")) -> WIN | S5: =IFERROR(_xlfn.XLOOKUP(Table15722354466784681112[[#This Row],[Rank]],$L$32:$Q$32,$L$31:$Q$31),"") -> Eduardo Ferreira | T5: 3rd
B6: B | C6: =B27 -> Gabriel Velloso | D6: =B29 -> Pedro Nagib | E6: 14 | F6: 18 | G6: =B28 -> Alex Abrantes | K6: =B31 -> Bruno Soares | L6: =IF(OR(Games_11[[#This Row],[SCORE 1]]="",Games_11[[#This Row],[SCORE 2]]=""),"",Games_11[[#This Row],[SCORE 1]]-Games_11[[#This Row],[SCORE 2]]) -> -4 | M6: =IF(OR(Games_11[[#This Row],[SCORE 1]]="",Games_11[[#This Row],[SCORE 2]]=""),"",Games_11[[#This Row],[SCORE 2]]-Games_11[[#This Row],[SCORE 1]]) -> 4 | N6: =IF(Games_11[[#This Row],[SCORE 1]]="","",Games_11[[#This Row],[SCORE 1]]) -> 14 | O6: =IF(Games_11[[#This Row],[SCORE 2]]="","",Games_11[[#This Row],[SCORE 2]]) -> 18 | P6: =IF(OR(Games_11[[#This Row],[SCORE 1]]="",Games_11[[#This Row],[SCORE 2]]=""),"",IF(Games_11[[#This Row],[SALDO 12]]>0, "WIN","LOSE")) -> LOSE | Q6: =IF(OR(Games_11[[#This Row],[SCORE 1]]="",Games_11[[#This Row],[SCORE 2]]=""),"",IF(Games_11[[#This Row],[SALDO 34]]>0, "WIN","LOSE")) -> WIN | S6: =IFERROR(_xlfn.XLOOKUP(Table15722354466784681112[[#This Row],[Rank]],$L$32:$Q$32,$L$31:$Q$31),"") -> João Barreto | T6: 4th
B7: C | C7: =B34 -> Thomas Zahn | D7: =B36 -> Bernardo Trotta | E7: 18 | F7: 20 | G7: =B35 -> Daniel Gaspar | K7: =B38 -> João Barreto | L7: =IF(OR(Games_11[[#This Row],[SCORE 1]]="",Games_11[[#This Row],[SCORE 2]]=""),"",Games_11[[#This Row],[SCORE 1]]-Games_11[[#This Row],[SCORE 2]]) -> -2 | M7: =IF(OR(Games_11[[#This Row],[SCORE 1]]="",Games_11[[#This Row],[SCORE 2]]=""),"",Games_11[[#This Row],[SCORE 2]]-Games_11[[#This Row],[SCORE 1]]) -> 2 | N7: =IF(Games_11[[#This Row],[SCORE 1]]="","",Games_11[[#This Row],[SCORE 1]]) -> 18 | O7: =IF(Games_11[[#This Row],[SCORE 2]]="","",Games_11[[#This Row],[SCORE 2]]) -> 20 | P7: =IF(OR(Games_11[[#This Row],[SCORE 1]]="",Games_11[[#This Row],[SCORE 2]]=""),"",IF(Games_11[[#This Row],[SALDO 12]]>0, "WIN","LOSE")) -> LOSE | Q7: =IF(OR(Games_11[[#This Row],[SCORE 1]]="",Games_11[[#This Row],[SCORE 2]]=""),"",IF(Games_11[[#This Row],[SALDO 34]]>0, "WIN","LOSE")) -> WIN | S7: =P25 -> Bruno Montini | T7: 5th
B8: A | C8: =B20 -> Guilherme Nascimento | D8: =B21 -> Renan Guiot | E8: 11 | F8: 18 | G8: =B23 -> Thyago Henrique | K8: =B24 -> Bruno Montini | L8: =IF(OR(Games_11[[#This Row],[SCORE 1]]="",Games_11[[#This Row],[SCORE 2]]=""),"",Games_11[[#This Row],[SCORE 1]]-Games_11[[#This Row],[SCORE 2]]) -> -7 | M8: =IF(OR(Games_11[[#This Row],[SCORE 1]]="",Games_11[[#This Row],[SCORE 2]]=""),"",Games_11[[#This Row],[SCORE 2]]-Games_11[[#This Row],[SCORE 1]]) -> 7 | N8: =IF(Games_11[[#This Row],[SCORE 1]]="","",Games_11[[#This Row],[SCORE 1]]) -> 11 | O8: =IF(Games_11[[#This Row],[SCORE 2]]="","",Games_11[[#This Row],[SCORE 2]]) -> 18 | P8: =IF(OR(Games_11[[#This Row],[SCORE 1]]="",Games_11[[#This Row],[SCORE 2]]=""),"",IF(Games_11[[#This Row],[SALDO 12]]>0, "WIN","LOSE")) -> LOSE | Q8: =IF(OR(Games_11[[#This Row],[SCORE 1]]="",Games_11[[#This Row],[SCORE 2]]=""),"",IF(Games_11[[#This Row],[SALDO 34]]>0, "WIN","LOSE")) -> WIN | S8: =P20 -> Gabriel Bugao | T8: 6th
B9: B | C9: =B27 -> Gabriel Velloso | D9: =B28 -> Alex Abrantes | E9: 10 | F9: 18 | G9: =B30 -> David Aitkens | K9: =B31 -> Bruno Soares | L9: =IF(OR(Games_11[[#This Row],[SCORE 1]]="",Games_11[[#This Row],[SCORE 2]]=""),"",Games_11[[#This Row],[SCORE 1]]-Games_11[[#This Row],[SCORE 2]]) -> -8 | M9: =IF(OR(Games_11[[#This Row],[SCORE 1]]="",Games_11[[#This Row],[SCORE 2]]=""),"",Games_11[[#This Row],[SCORE 2]]-Games_11[[#This Row],[SCORE 1]]) -> 8 | N9: =IF(Games_11[[#This Row],[SCORE 1]]="","",Games_11[[#This Row],[SCORE 1]]) -> 10 | O9: =IF(Games_11[[#This Row],[SCORE 2]]="","",Games_11[[#This Row],[SCORE 2]]) -> 18 | P9: =IF(OR(Games_11[[#This Row],[SCORE 1]]="",Games_11[[#This Row],[SCORE 2]]=""),"",IF(Games_11[[#This Row],[SALDO 12]]>0, "WIN","LOSE")) -> LOSE | Q9: =IF(OR(Games_11[[#This Row],[SCORE 1]]="",Games_11[[#This Row],[SCORE 2]]=""),"",IF(Games_11[[#This Row],[SALDO 34]]>0, "WIN","LOSE")) -> WIN | S9: =IF($L$31="","",_xlfn.XLOOKUP(Table15722354466784681112[[#This Row],[Rank]],$K$20:$K$38,$J$20:$J$38)) -> Renan Guiot | T9: 7th
B10: C | C10: =B34 -> Thomas Zahn | D10: =B35 -> Daniel Gaspar | E10: 8 | F10: 18 | G10: =B37 -> Eduardo Ferreira | K10: =B38 -> João Barreto | L10: =IF(OR(Games_11[[#This Row],[SCORE 1]]="",Games_11[[#This Row],[SCORE 2]]=""),"",Games_11[[#This Row],[SCORE 1]]-Games_11[[#This Row],[SCORE 2]]) -> -10 | M10: =IF(OR(Games_11[[#This Row],[SCORE 1]]="",Games_11[[#This Row],[SCORE 2]]=""),"",Games_11[[#This Row],[SCORE 2]]-Games_11[[#This Row],[SCORE 1]]) -> 10 | N10: =IF(Games_11[[#This Row],[SCORE 1]]="","",Games_11[[#This Row],[SCORE 1]]) -> 8 | O10: =IF(Games_11[[#This Row],[SCORE 2]]="","",Games_11[[#This Row],[SCORE 2]]) -> 18 | P10: =IF(OR(Games_11[[#This Row],[SCORE 1]]="",Games_11[[#This Row],[SCORE 2]]=""),"",IF(Games_11[[#This Row],[SALDO 12]]>0, "WIN","LOSE")) -> LOSE | Q10: =IF(OR(Games_11[[#This Row],[SCORE 1]]="",Games_11[[#This Row],[SCORE 2]]=""),"",IF(Games_11[[#This Row],[SALDO 34]]>0, "WIN","LOSE")) -> WIN | S10: =IF($L$31="","",_xlfn.XLOOKUP(Table15722354466784681112[[#This Row],[Rank]],$K$20:$K$38,$J$20:$J$38)) -> David Aitkens | T10: 8th
B11: A | C11: =B20 -> Guilherme Nascimento | D11: =B24 -> Bruno Montini | E11: 20 | F11: 22 | G11: =B22 -> Gabriel Bugao | K11: =B23 -> Thyago Henrique | L11: =IF(OR(Games_11[[#This Row],[SCORE 1]]="",Games_11[[#This Row],[SCORE 2]]=""),"",Games_11[[#This Row],[SCORE 1]]-Games_11[[#This Row],[SCORE 2]]) -> -2 | M11: =IF(OR(Games_11[[#This Row],[SCORE 1]]="",Games_11[[#This Row],[SCORE 2]]=""),"",Games_11[[#This Row],[SCORE 2]]-Games_11[[#This Row],[SCORE 1]]) -> 2 | N11: =IF(Games_11[[#This Row],[SCORE 1]]="","",Games_11[[#This Row],[SCORE 1]]) -> 20 | O11: =IF(Games_11[[#This Row],[SCORE 2]]="","",Games_11[[#This Row],[SCORE 2]]) -> 22 | P11: =IF(OR(Games_11[[#This Row],[SCORE 1]]="",Games_11[[#This Row],[SCORE 2]]=""),"",IF(Games_11[[#This Row],[SALDO 12]]>0, "WIN","LOSE")) -> LOSE | Q11: =IF(OR(Games_11[[#This Row],[SCORE 1]]="",Games_11[[#This Row],[SCORE 2]]=""),"",IF(Games_11[[#This Row],[SALDO 34]]>0, "WIN","LOSE")) -> WIN | S11: {=IF(COUNTBLANK(Games_11[[SCORE 1]:[SCORE 2]])=0,_xlfn.TEXTJOIN(", ", TRUE, _xlfn._xlws.FILTER($J$20:$J$38, $K$20:$K$38=T11, "")),"")} -> Thyago Henrique | T11: 9th
B12: B | C12: =B27 -> Gabriel Velloso | D12: =B31 -> Bruno Soares | E12: 9 | F12: 18 | G12: =B29 -> Pedro Nagib | K12: =B30 -> David Aitkens | L12: =IF(OR(Games_11[[#This Row],[SCORE 1]]="",Games_11[[#This Row],[SCORE 2]]=""),"",Games_11[[#This Row],[SCORE 1]]-Games_11[[#This Row],[SCORE 2]]) -> -9 | M12: =IF(OR(Games_11[[#This Row],[SCORE 1]]="",Games_11[[#This Row],[SCORE 2]]=""),"",Games_11[[#This Row],[SCORE 2]]-Games_11[[#This Row],[SCORE 1]]) -> 9 | N12: =IF(Games_11[[#This Row],[SCORE 1]]="","",Games_11[[#This Row],[SCORE 1]]) -> 9 | O12: =IF(Games_11[[#This Row],[SCORE 2]]="","",Games_11[[#This Row],[SCORE 2]]) -> 18 | P12: =IF(OR(Games_11[[#This Row],[SCORE 1]]="",Games_11[[#This Row],[SCORE 2]]=""),"",IF(Games_11[[#This Row],[SALDO 12]]>0, "WIN","LOSE")) -> LOSE | Q12: =IF(OR(Games_11[[#This Row],[SCORE 1]]="",Games_11[[#This Row],[SCORE 2]]=""),"",IF(Games_11[[#This Row],[SALDO 34]]>0, "WIN","LOSE")) -> WIN | S12: {=IF(COUNTBLANK(Games_11[[SCORE 1]:[SCORE 2]])=0,_xlfn.TEXTJOIN(", ", TRUE, _xlfn._xlws.FILTER($J$20:$J$38, $K$20:$K$38=T12, "")),"")} -> Daniel Gaspar | T12: 10th
B13: C | C13: =B34 -> Thomas Zahn | D13: =B38 -> João Barreto | E13: 18 | F13: 20 | G13: =B36 -> Bernardo Trotta | K13: =B37 -> Eduardo Ferreira | L13: =IF(OR(Games_11[[#This Row],[SCORE 1]]="",Games_11[[#This Row],[SCORE 2]]=""),"",Games_11[[#This Row],[SCORE 1]]-Games_11[[#This Row],[SCORE 2]]) -> -2 | M13: =IF(OR(Games_11[[#This Row],[SCORE 1]]="",Games_11[[#This Row],[SCORE 2]]=""),"",Games_11[[#This Row],[SCORE 2]]-Games_11[[#This Row],[SCORE 1]]) -> 2 | N13: =IF(Games_11[[#This Row],[SCORE 1]]="","",Games_11[[#This Row],[SCORE 1]]) -> 18 | O13: =IF(Games_11[[#This Row],[SCORE 2]]="","",Games_11[[#This Row],[SCORE 2]]) -> 20 | P13: =IF(OR(Games_11[[#This Row],[SCORE 1]]="",Games_11[[#This Row],[SCORE 2]]=""),"",IF(Games_11[[#This Row],[SALDO 12]]>0, "WIN","LOSE")) -> LOSE | Q13: =IF(OR(Games_11[[#This Row],[SCORE 1]]="",Games_11[[#This Row],[SCORE 2]]=""),"",IF(Games_11[[#This Row],[SALDO 34]]>0, "WIN","LOSE")) -> WIN | S13: {=IF(COUNTBLANK(Games_11[[SCORE 1]:[SCORE 2]])=0,_xlfn.TEXTJOIN(", ", TRUE, _xlfn._xlws.FILTER($J$20:$J$38, $K$20:$K$38=T13, "")),"")} -> Alex Abrantes | T13: 11th
B14: A | C14: =B22 -> Gabriel Bugao | D14: =B24 -> Bruno Montini | E14: 18 | F14: 16 | G14: =B21 -> Renan Guiot | K14: =B23 -> Thyago Henrique | L14: =IF(OR(Games_11[[#This Row],[SCORE 1]]="",Games_11[[#This Row],[SCORE 2]]=""),"",Games_11[[#This Row],[SCORE 1]]-Games_11[[#This Row],[SCORE 2]]) -> 2 | M14: =IF(OR(Games_11[[#This Row],[SCORE 1]]="",Games_11[[#This Row],[SCORE 2]]=""),"",Games_11[[#This Row],[SCORE 2]]-Games_11[[#This Row],[SCORE 1]]) -> -2 | N14: =IF(Games_11[[#This Row],[SCORE 1]]="","",Games_11[[#This Row],[SCORE 1]]) -> 18 | O14: =IF(Games_11[[#This Row],[SCORE 2]]="","",Games_11[[#This Row],[SCORE 2]]) -> 16 | P14: =IF(OR(Games_11[[#This Row],[SCORE 1]]="",Games_11[[#This Row],[SCORE 2]]=""),"",IF(Games_11[[#This Row],[SALDO 12]]>0, "WIN","LOSE")) -> WIN | Q14: =IF(OR(Games_11[[#This Row],[SCORE 1]]="",Games_11[[#This Row],[SCORE 2]]=""),"",IF(Games_11[[#This Row],[SALDO 34]]>0, "WIN","LOSE")) -> LOSE | S14: {=IF(COUNTBLANK(Games_11[[SCORE 1]:[SCORE 2]])=0,_xlfn.TEXTJOIN(", ", TRUE, _xlfn._xlws.FILTER($J$20:$J$38, $K$20:$K$38=T14, "")),"")} -> Thomas Zahn | T14: 12th
B15: B | C15: =B29 -> Pedro Nagib | D15: =B31 -> Bruno Soares | E15: 18 | F15: 5 | G15: =B28 -> Alex Abrantes | K15: =B30 -> David Aitkens | L15: =IF(OR(Games_11[[#This Row],[SCORE 1]]="",Games_11[[#This Row],[SCORE 2]]=""),"",Games_11[[#This Row],[SCORE 1]]-Games_11[[#This Row],[SCORE 2]]) -> 13 | M15: =IF(OR(Games_11[[#This Row],[SCORE 1]]="",Games_11[[#This Row],[SCORE 2]]=""),"",Games_11[[#This Row],[SCORE 2]]-Games_11[[#This Row],[SCORE 1]]) -> -13 | N15: =IF(Games_11[[#This Row],[SCORE 1]]="","",Games_11[[#This Row],[SCORE 1]]) -> 18 | O15: =IF(Games_11[[#This Row],[SCORE 2]]="","",Games_11[[#This Row],[SCORE 2]]) -> 5 | P15: =IF(OR(Games_11[[#This Row],[SCORE 1]]="",Games_11[[#This Row],[SCORE 2]]=""),"",IF(Games_11[[#This Row],[SALDO 12]]>0, "WIN","LOSE")) -> WIN | Q15: =IF(OR(Games_11[[#This Row],[SCORE 1]]="",Games_11[[#This Row],[SCORE 2]]=""),"",IF(Games_11[[#This Row],[SALDO 34]]>0, "WIN","LOSE")) -> LOSE | S15: {=IF(COUNTBLANK(Games_11[[SCORE 1]:[SCORE 2]])=0,_xlfn.TEXTJOIN(", ", TRUE, _xlfn._xlws.FILTER($J$20:$J$38, $K$20:$K$38=T15, "")),"")} -> Bernardo Trotta | T15: 13th
B16: C | C16: =B36 -> Bernardo Trotta | D16: =B38 -> João Barreto | E16: 14 | F16: 18 | G16: =B35 -> Daniel Gaspar | K16: =B37 -> Eduardo Ferreira | L16: =IF(OR(Games_11[[#This Row],[SCORE 1]]="",Games_11[[#This Row],[SCORE 2]]=""),"",Games_11[[#This Row],[SCORE 1]]-Games_11[[#This Row],[SCORE 2]]) -> -4 | M16: =IF(OR(Games_11[[#This Row],[SCORE 1]]="",Games_11[[#This Row],[SCORE 2]]=""),"",Games_11[[#This Row],[SCORE 2]]-Games_11[[#This Row],[SCORE 1]]) -> 4 | N16: =IF(Games_11[[#This Row],[SCORE 1]]="","",Games_11[[#This Row],[SCORE 1]]) -> 14 | O16: =IF(Games_11[[#This Row],[SCORE 2]]="","",Games_11[[#This Row],[SCORE 2]]) -> 18 | P16: =IF(OR(Games_11[[#This Row],[SCORE 1]]="",Games_11[[#This Row],[SCORE 2]]=""),"",IF(Games_11[[#This Row],[SALDO 12]]>0, "WIN","LOSE")) -> LOSE | Q16: =IF(OR(Games_11[[#This Row],[SCORE 1]]="",Games_11[[#This Row],[SCORE 2]]=""),"",IF(Games_11[[#This Row],[SALDO 34]]>0, "WIN","LOSE")) -> WIN | S16: {=IF(COUNTBLANK(Games_11[[SCORE 1]:[SCORE 2]])=0,_xlfn.TEXTJOIN(", ", TRUE, _xlfn._xlws.FILTER($J$20:$J$38, $K$20:$K$38=T16, "")),"")} -> Guilherme Nascimento | T16: 14th
S17: {=IF(COUNTBLANK(Games_11[[SCORE 1]:[SCORE 2]])=0,_xlfn.TEXTJOIN(", ", TRUE, _xlfn._xlws.FILTER($J$20:$J$38, $K$20:$K$38=T17, "")),"")} -> Gabriel Velloso | T17: 15th
A18: GROUP PHASE | L18: QUARTAS
A19: Group | B19: Atheletes | C19: WIN | D19: LOSE | E19: Saldo | F19: PM | G19: Rank | H19: Rank Support | I19: Joint rank sys. | J19: Athelete | K19: Overall Rank | L19: Athelete 1 | M19: Athelete 2 | N19: SCORE | P19: Athelete 3 | Q19: Athelete 4
A20: A | B20: Guilherme Nascimento | C20: =SUM(COUNTIFS(Games_11[ATHLETE 1],Analysis_22[[#This Row],[Atheletes ]],Games_11[RESULT 12],"win"),COUNTIFS(Games_11[ATHLETE 2],Analysis_22[[#This Row],[Atheletes ]],Games_11[RESULT 12],"win"),COUNTIFS(Games_11[ATHLETE 3],Analysis_22[[#This Row],[Atheletes ]],Games_11[RESULT 34],"win"),COUNTIFS(Games_11[ATHLETE 4],Analysis_22[[#This Row],[Atheletes ]],Games_11[RESULT 34],"win")) -> 0 | D20: =SUM(COUNTIFS(Games_11[ATHLETE 1],Analysis_22[[#This Row],[Atheletes ]],Games_11[RESULT 12],"lose"),COUNTIFS(Games_11[ATHLETE 2],Analysis_22[[#This Row],[Atheletes ]],Games_11[RESULT 12],"lose"),COUNTIFS(Games_11[ATHLETE 3],Analysis_22[[#This Row],[Atheletes ]],Games_11[RESULT 34],"lose"),COUNTIFS(Games_11[ATHLETE 4],Analysis_22[[#This Row],[Atheletes ]],Games_11[RESULT 34],"lose")) -> 4 | E20: =SUM(SUMIF(Games_11[ATHLETE 1],Analysis_22[[#This Row],[Atheletes ]],Games_11[SALDO 12]),SUMIF(Games_11[ATHLETE 2],Analysis_22[[#This Row],[Atheletes ]],Games_11[SALDO 12]),SUMIF(Games_11[ATHLETE 3],Analysis_22[[#This Row],[Atheletes ]],Games_11[SALDO 34]),SUMIF(Games_11[ATHLETE 4],Analysis_22[[#This Row],[Atheletes ]],Games_11[SALDO 34])) -> -22 | F20: =SUM(SUMIF(Games_11[ATHLETE 1],Analysis_22[[#This Row],[Atheletes ]],Games_11[PM 12]),SUMIF(Games_11[ATHLETE 2],Analysis_22[[#This Row],[Atheletes ]],Games_11[PM 12]),SUMIF(Games_11[ATHLETE 3],Analysis_22[[#This Row],[Atheletes ]],Games_11[PM 34]),SUMIF(Games_11[ATHLETE 4],Analysis_22[[#This Row],[Atheletes ]],Games_11[PM 34])) -> 54 | G20: =IF(COUNTBLANK(Games_11[[SCORE 1]:[SCORE 2]])=0,IF(RANK(H20,$H$20:$H$24)=1,RANK(H20,$H$20:$H$24)&"st",IF(RANK(H20,$H$20:$H$24)=2,RANK(H20,$H$20:$H$24)&"nd",IF(RANK(H20,$H$20:$H$24)=3,RANK(H20,$H$20:$H$24)&"rd",RANK(H20,$H$20:$H$24)&"th"))),"") -> 5th | H20: =Analysis_22[[#This Row],[WIN]]*1000000+Analysis_22[[#This Row],[Saldo]]*1000+Analysis_22[[#This Row],[PM]] -> -21946 | I20: =H20 -> -21946 | J20: =Analysis_22[[#This Row],[Atheletes ]] -> Guilherme Nascimento | K20: =IF(RANK(I20,$I$20:$I$38)=1,RANK(I20,$I$20:$I$38)&"st",IF(RANK(I20,$I$20:$I$38)=2,RANK(I20,$I$20:$I$38)&"nd",IF(RANK(I20,$I$20:$I$38)=3,RANK(I20,$I$20:$I$38)&"rd",RANK(I20,$I$20:$I$38)&"th"))) -> 14th | L20: {=IF(COUNTBLANK(Games_11[[SCORE 1]:[SCORE 2]])=0,_xlfn.TEXTJOIN(", ", TRUE, _xlfn._xlws.FILTER($J$20:$J$38, $K$20:$K$38=T3,"")),"")} -> Eduardo Ferreira | M20: =B38 -> João Barreto | N20: 18 | O20: 11 | P20: =B22 -> Gabriel Bugao | Q20: =B21 -> Renan Guiot
A21: A | B21: Renan Guiot | C21: =SUM(COUNTIFS(Games_11[ATHLETE 1],Analysis_22[[#This Row],[Atheletes ]],Games_11[RESULT 12],"win"),COUNTIFS(Games_11[ATHLETE 2],Analysis_22[[#This Row],[Atheletes ]],Games_11[RESULT 12],"win"),COUNTIFS(Games_11[ATHLETE 3],Analysis_22[[#This Row],[Atheletes ]],Games_11[RESULT 34],"win"),COUNTIFS(Games_11[ATHLETE 4],Analysis_22[[#This Row],[Atheletes ]],Games_11[RESULT 34],"win")) -> 2 | D21: =SUM(COUNTIFS(Games_11[ATHLETE 1],Analysis_22[[#This Row],[Atheletes ]],Games_11[RESULT 12],"lose"),COUNTIFS(Games_11[ATHLETE 2],Analysis_22[[#This Row],[Atheletes ]],Games_11[RESULT 12],"lose"),COUNTIFS(Games_11[ATHLETE 3],Analysis_22[[#This Row],[Atheletes ]],Games_11[RESULT 34],"lose"),COUNTIFS(Games_11[ATHLETE 4],Analysis_22[[#This Row],[Atheletes ]],Games_11[RESULT 34],"lose")) -> 2 | E21: =SUM(SUMIF(Games_11[ATHLETE 1],Analysis_22[[#This Row],[Atheletes ]],Games_11[SALDO 12]),SUMIF(Games_11[ATHLETE 2],Analysis_22[[#This Row],[Atheletes ]],Games_11[SALDO 12]),SUMIF(Games_11[ATHLETE 3],Analysis_22[[#This Row],[Atheletes ]],Games_11[SALDO 34]),SUMIF(Games_11[ATHLETE 4],Analysis_22[[#This Row],[Atheletes ]],Games_11[SALDO 34])) -> 4 | F21: =SUM(SUMIF(Games_11[ATHLETE 1],Analysis_22[[#This Row],[Atheletes ]],Games_11[PM 12]),SUMIF(Games_11[ATHLETE 2],Analysis_22[[#This Row],[Atheletes ]],Games_11[PM 12]),SUMIF(Games_11[ATHLETE 3],Analysis_22[[#This Row],[Atheletes ]],Games_11[PM 34]),SUMIF(Games_11[ATHLETE 4],Analysis_22[[#This Row],[Atheletes ]],Games_11[PM 34])) -> 63 | G21: =IF(COUNTBLANK(Games_11[[SCORE 1]:[SCORE 2]])=0,IF(RANK(H21,$H$20:$H$24)=1,RANK(H21,$H$20:$H$24)&"st",IF(RANK(H21,$H$20:$H$24)=2,RANK(H21,$H$20:$H$24)&"nd",IF(RANK(H21,$H$20:$H$24)=3,RANK(H21,$H$20:$H$24)&"rd",RANK(H21,$H$20:$H$24)&"th"))),"") -> 3rd | H21: =Analysis_22[[#This Row],[WIN]]*1000000+Analysis_22[[#This Row],[Saldo]]*1000+Analysis_22[[#This Row],[PM]] -> 2004063 | I21: =H21 -> 2004063 | J21: =Analysis_22[[#This Row],[Atheletes ]] -> Renan Guiot | K21: =IF(RANK(I21,$I$20:$I$38)=1,RANK(I21,$I$20:$I$38)&"st",IF(RANK(I21,$I$20:$I$38)=2,RANK(I21,$I$20:$I$38)&"nd",IF(RANK(I21,$I$20:$I$38)=3,RANK(I21,$I$20:$I$38)&"rd",RANK(I21,$I$20:$I$38)&"th"))) -> 7th
A22: A | B22: Gabriel Bugao | C22: =SUM(COUNTIFS(Games_11[ATHLETE 1],Analysis_22[[#This Row],[Atheletes ]],Games_11[RESULT 12],"win"),COUNTIFS(Games_11[ATHLETE 2],Analysis_22[[#This Row],[Atheletes ]],Games_11[RESULT 12],"win"),COUNTIFS(Games_11[ATHLETE 3],Analysis_22[[#This Row],[Atheletes ]],Games_11[RESULT 34],"win"),COUNTIFS(Games_11[ATHLETE 4],Analysis_22[[#This Row],[Atheletes ]],Games_11[RESULT 34],"win")) -> 3 | D22: =SUM(COUNTIFS(Games_11[ATHLETE 1],Analysis_22[[#This Row],[Atheletes ]],Games_11[RESULT 12],"lose"),COUNTIFS(Games_11[ATHLETE 2],Analysis_22[[#This Row],[Atheletes ]],Games_11[RESULT 12],"lose"),COUNTIFS(Games_11[ATHLETE 3],Analysis_22[[#This Row],[Atheletes ]],Games_11[RESULT 34],"lose"),COUNTIFS(Games_11[ATHLETE 4],Analysis_22[[#This Row],[Atheletes ]],Games_11[RESULT 34],"lose")) -> 1 | E22: =SUM(SUMIF(Games_11[ATHLETE 1],Analysis_22[[#This Row],[Atheletes ]],Games_11[SALDO 12]),SUMIF(Games_11[ATHLETE 2],Analysis_22[[#This Row],[Atheletes ]],Games_11[SALDO 12]),SUMIF(Games_11[ATHLETE 3],Analysis_22[[#This Row],[Atheletes ]],Games_11[SALDO 34]),SUMIF(Games_11[ATHLETE 4],Analysis_22[[#This Row],[Atheletes ]],Games_11[SALDO 34])) -> 9 | F22: =SUM(SUMIF(Games_11[ATHLETE 1],Analysis_22[[#This Row],[Atheletes ]],Games_11[PM 12]),SUMIF(Games_11[ATHLETE 2],Analysis_22[[#This Row],[Atheletes ]],Games_11[PM 12]),SUMIF(Games_11[ATHLETE 3],Analysis_22[[#This Row],[Atheletes ]],Games_11[PM 34]),SUMIF(Games_11[ATHLETE 4],Analysis_22[[#This Row],[Atheletes ]],Games_11[PM 34])) -> 72 | G22: =IF(COUNTBLANK(Games_11[[SCORE 1]:[SCORE 2]])=0,IF(RANK(H22,$H$20:$H$24)=1,RANK(H22,$H$20:$H$24)&"st",IF(RANK(H22,$H$20:$H$24)=2,RANK(H22,$H$20:$H$24)&"nd",IF(RANK(H22,$H$20:$H$24)=3,RANK(H22,$H$20:$H$24)&"rd",RANK(H22,$H$20:$H$24)&"th"))),"") -> 2nd | H22: =Analysis_22[[#This Row],[WIN]]*1000000+Analysis_22[[#This Row],[Saldo]]*1000+Analysis_22[[#This Row],[PM]] -> 3009072 | I22: =H22 -> 3009072 | J22: =Analysis_22[[#This Row],[Atheletes ]] -> Gabriel Bugao | K22: =IF(RANK(I22,$I$20:$I$38)=1,RANK(I22,$I$20:$I$38)&"st",IF(RANK(I22,$I$20:$I$38)=2,RANK(I22,$I$20:$I$38)&"nd",IF(RANK(I22,$I$20:$I$38)=3,RANK(I22,$I$20:$I$38)&"rd",RANK(I22,$I$20:$I$38)&"th"))) -> 5th
A23: A | B23: Thyago Henrique | C23: =SUM(COUNTIFS(Games_11[ATHLETE 1],Analysis_22[[#This Row],[Atheletes ]],Games_11[RESULT 12],"win"),COUNTIFS(Games_11[ATHLETE 2],Analysis_22[[#This Row],[Atheletes ]],Games_11[RESULT 12],"win"),COUNTIFS(Games_11[ATHLETE 3],Analysis_22[[#This Row],[Atheletes ]],Games_11[RESULT 34],"win"),COUNTIFS(Games_11[ATHLETE 4],Analysis_22[[#This Row],[Atheletes ]],Games_11[RESULT 34],"win")) -> 2 | D23: =SUM(COUNTIFS(Games_11[ATHLETE 1],Analysis_22[[#This Row],[Atheletes ]],Games_11[RESULT 12],"lose"),COUNTIFS(Games_11[ATHLETE 2],Analysis_22[[#This Row],[Atheletes ]],Games_11[RESULT 12],"lose"),COUNTIFS(Games_11[ATHLETE 3],Analysis_22[[#This Row],[Atheletes ]],Games_11[RESULT 34],"lose"),COUNTIFS(Games_11[ATHLETE 4],Analysis_22[[#This Row],[Atheletes ]],Games_11[RESULT 34],"lose")) -> 2 | E23: =SUM(SUMIF(Games_11[ATHLETE 1],Analysis_22[[#This Row],[Atheletes ]],Games_11[SALDO 12]),SUMIF(Games_11[ATHLETE 2],Analysis_22[[#This Row],[Atheletes ]],Games_11[SALDO 12]),SUMIF(Games_11[ATHLETE 3],Analysis_22[[#This Row],[Atheletes ]],Games_11[SALDO 34]),SUMIF(Games_11[ATHLETE 4],Analysis_22[[#This Row],[Atheletes ]],Games_11[SALDO 34])) -> -2 | F23: =SUM(SUMIF(Games_11[ATHLETE 1],Analysis_22[[#This Row],[Atheletes ]],Games_11[PM 12]),SUMIF(Games_11[ATHLETE 2],Analysis_22[[#This Row],[Atheletes ]],Games_11[PM 12]),SUMIF(Games_11[ATHLETE 3],Analysis_22[[#This Row],[Atheletes ]],Games_11[PM 34]),SUMIF(Games_11[ATHLETE 4],Analysis_22[[#This Row],[Atheletes ]],Games_11[PM 34])) -> 65 | G23: =IF(COUNTBLANK(Games_11[[SCORE 1]:[SCORE 2]])=0,IF(RANK(H23,$H$20:$H$24)=1,RANK(H23,$H$20:$H$24)&"st",IF(RANK(H23,$H$20:$H$24)=2,RANK(H23,$H$20:$H$24)&"nd",IF(RANK(H23,$H$20:$H$24)=3,RANK(H23,$H$20:$H$24)&"rd",RANK(H23,$H$20:$H$24)&"th"))),"") -> 4th | H23: =Analysis_22[[#This Row],[WIN]]*1000000+Analysis_22[[#This Row],[Saldo]]*1000+Analysis_22[[#This Row],[PM]] -> 1998065 | I23: =H23 -> 1998065 | J23: =Analysis_22[[#This Row],[Atheletes ]] -> Thyago Henrique | K23: =IF(RANK(I23,$I$20:$I$38)=1,RANK(I23,$I$20:$I$38)&"st",IF(RANK(I23,$I$20:$I$38)=2,RANK(I23,$I$20:$I$38)&"nd",IF(RANK(I23,$I$20:$I$38)=3,RANK(I23,$I$20:$I$38)&"rd",RANK(I23,$I$20:$I$38)&"th"))) -> 9th
A24: A | B24: Bruno Montini | C24: =SUM(COUNTIFS(Games_11[ATHLETE 1],Analysis_22[[#This Row],[Atheletes ]],Games_11[RESULT 12],"win"),COUNTIFS(Games_11[ATHLETE 2],Analysis_22[[#This Row],[Atheletes ]],Games_11[RESULT 12],"win"),COUNTIFS(Games_11[ATHLETE 3],Analysis_22[[#This Row],[Atheletes ]],Games_11[RESULT 34],"win"),COUNTIFS(Games_11[ATHLETE 4],Analysis_22[[#This Row],[Atheletes ]],Games_11[RESULT 34],"win")) -> 3 | D24: =SUM(COUNTIFS(Games_11[ATHLETE 1],Analysis_22[[#This Row],[Atheletes ]],Games_11[RESULT 12],"lose"),COUNTIFS(Games_11[ATHLETE 2],Analysis_22[[#This Row],[Atheletes ]],Games_11[RESULT 12],"lose"),COUNTIFS(Games_11[ATHLETE 3],Analysis_22[[#This Row],[Atheletes ]],Games_11[RESULT 34],"lose"),COUNTIFS(Games_11[ATHLETE 4],Analysis_22[[#This Row],[Atheletes ]],Games_11[RESULT 34],"lose")) -> 1 | E24: =SUM(SUMIF(Games_11[ATHLETE 1],Analysis_22[[#This Row],[Atheletes ]],Games_11[SALDO 12]),SUMIF(Games_11[ATHLETE 2],Analysis_22[[#This Row],[Atheletes ]],Games_11[SALDO 12]),SUMIF(Games_11[ATHLETE 3],Analysis_22[[#This Row],[Atheletes ]],Games_11[SALDO 34]),SUMIF(Games_11[ATHLETE 4],Analysis_22[[#This Row],[Atheletes ]],Games_11[SALDO 34])) -> 11 | F24: =SUM(SUMIF(Games_11[ATHLETE 1],Analysis_22[[#This Row],[Atheletes ]],Games_11[PM 12]),SUMIF(Games_11[ATHLETE 2],Analysis_22[[#This Row],[Atheletes ]],Games_11[PM 12]),SUMIF(Games_11[ATHLETE 3],Analysis_22[[#This Row],[Atheletes ]],Games_11[PM 34]),SUMIF(Games_11[ATHLETE 4],Analysis_22[[#This Row],[Atheletes ]],Games_11[PM 34])) -> 74 | G24: =IF(COUNTBLANK(Games_11[[SCORE 1]:[SCORE 2]])=0,IF(RANK(H24,$H$20:$H$24)=1,RANK(H24,$H$20:$H$24)&"st",IF(RANK(H24,$H$20:$H$24)=2,RANK(H24,$H$20:$H$24)&"nd",IF(RANK(H24,$H$20:$H$24)=3,RANK(H24,$H$20:$H$24)&"rd",RANK(H24,$H$20:$H$24)&"th"))),"") -> 1st | H24: =Analysis_22[[#This Row],[WIN]]*1000000+Analysis_22[[#This Row],[Saldo]]*1000+Analysis_22[[#This Row],[PM]] -> 3011074 | I24: =H24 -> 3011074 | J24: =Analysis_22[[#This Row],[Atheletes ]] -> Bruno Montini | K24: =IF(RANK(I24,$I$20:$I$38)=1,RANK(I24,$I$20:$I$38)&"st",IF(RANK(I24,$I$20:$I$38)=2,RANK(I24,$I$20:$I$38)&"nd",IF(RANK(I24,$I$20:$I$38)=3,RANK(I24,$I$20:$I$38)&"rd",RANK(I24,$I$20:$I$38)&"th"))) -> 4th | L24: Athelete 1 | M24: Athelete 2 | N24: SCORE | P24: Athelete 3 | Q24: Athelete 4 | S24: Support indexes for ranking system.
L25: =B29 -> Pedro Nagib | M25: =B31 -> Bruno Soares | N25: 18 | O25: 12 | P25: =B24 -> Bruno Montini | Q25: =B30 -> David Aitkens
A26: Group | B26: Atheletes | C26: WIN | D26: LOSE | E26: Saldo | F26: PM | G26: Rank | H26: Rank Support
A27: B | B27: Gabriel Velloso | C27: =SUM(COUNTIFS(Games_11[ATHLETE 1],Analsyis_23[[#This Row],[Atheletes ]],Games_11[RESULT 12],"win"),COUNTIFS(Games_11[ATHLETE 2],Analsyis_23[[#This Row],[Atheletes ]],Games_11[RESULT 12],"win"),COUNTIFS(Games_11[ATHLETE 3],Analsyis_23[[#This Row],[Atheletes ]],Games_11[RESULT 34],"win"),COUNTIFS(Games_11[ATHLETE 4],Analsyis_23[[#This Row],[Atheletes ]],Games_11[RESULT 34],"win")) -> 0 | D27: =SUM(COUNTIFS(Games_11[ATHLETE 1],Analsyis_23[[#This Row],[Atheletes ]],Games_11[RESULT 12],"lose"),COUNTIFS(Games_11[ATHLETE 2],Analsyis_23[[#This Row],[Atheletes ]],Games_11[RESULT 12],"lose"),COUNTIFS(Games_11[ATHLETE 3],Analsyis_23[[#This Row],[Atheletes ]],Games_11[RESULT 34],"lose"),COUNTIFS(Games_11[ATHLETE 4],Analsyis_23[[#This Row],[Atheletes ]],Games_11[RESULT 34],"lose")) -> 4 | E27: =SUM(SUMIF(Games_11[ATHLETE 1],Analsyis_23[[#This Row],[Atheletes ]],Games_11[SALDO 12]),SUMIF(Games_11[ATHLETE 2],Analsyis_23[[#This Row],[Atheletes ]],Games_11[SALDO 12]),SUMIF(Games_11[ATHLETE 3],Analsyis_23[[#This Row],[Atheletes ]],Games_11[SALDO 34]),SUMIF(Games_11[ATHLETE 4],Analsyis_23[[#This Row],[Atheletes ]],Games_11[SALDO 34])) -> -23 | F27: =SUM(SUMIF(Games_11[ATHLETE 1],Analsyis_23[[#This Row],[Atheletes ]],Games_11[PM 12]),SUMIF(Games_11[ATHLETE 2],Analsyis_23[[#This Row],[Atheletes ]],Games_11[PM 12]),SUMIF(Games_11[ATHLETE 3],Analsyis_23[[#This Row],[Atheletes ]],Games_11[PM 34]),SUMIF(Games_11[ATHLETE 4],Analsyis_23[[#This Row],[Atheletes ]],Games_11[PM 34])) -> 51 | G27: =IF(COUNTBLANK(Games_11[[SCORE 1]:[SCORE 2]])=0,IF(RANK(H27,$H$27:$H$31)=1,RANK(H27,$H$27:$H$31)&"st",IF(RANK(H27,$H$27:$H$31)=2,RANK(H27,$H$27:$H$31)&"nd",IF(RANK(H27,$H$27:$H$31)=3,RANK(H27,$H$27:$H$31)&"rd",RANK(H27,$H$27:$H$31)&"th"))),"") -> 5th | H27: =Analsyis_23[[#This Row],[WIN]]*1000000+Analsyis_23[[#This Row],[Saldo]]*1000+Analsyis_23[[#This Row],[PM]] -> -22949 | I27: =H27 -> -22949 | J27: =B27 -> Gabriel Velloso | K27: =IF(RANK(I27,$I$20:$I$38)=1,RANK(I27,$I$20:$I$38)&"st",IF(RANK(I27,$I$20:$I$38)=2,RANK(I27,$I$20:$I$38)&"nd",IF(RANK(I27,$I$20:$I$38)=3,RANK(I27,$I$20:$I$38)&"rd",RANK(I27,$I$20:$I$38)&"th"))) -> 15th
